
/*package clase4.excepcion;


public class Excepcion{

    public static void main(String[] args) {
        //Excepcion.testExcepcion();
        //Excepcion.testExcepcion2();
        Excepcion.testException3();
    }
/*public static void testExcepcion() {
        /*    try 
        int dividendo = 10;
        int divisor = 0;
        
        int resultado = dividendo/divisor;
        
    } catch (Exception e) {
            System.out.println(" hubo un peque√±o error");
    }
  }*/
 /*  public static void testExcepcion2(){
       try{
        int dividendo = 10;
        int divisor = 0;
        
        int resultado = dividendo/divisor;
        
        int[] array = new int[2];
        array [10] = 100;
        
    }catch (ArrayIndexOutOfBoundsException e) {
            System.out.println(" hubo un error de array");
    }catch (ArithmeticException e){
            System.out.println(" hubo un error matematico");        
    }finally{
           System.out.println(" fin de este programa");
       }      
 } */
    
 /*   public static void testException3() {
        try {
            int[] numeros = null;
            
            for (int i = 0; i < 11; i++) {
                int j = numeros[i];
                
            }
        } catch (NullPointerException e) {
            System.out.println("error un array null");
            e.printStackTrace();
            
        }finally{
            System.out.println("la aplicacion en este momento esta terminada");}
    }
    
  
}   */
